<mujoco model="ballbot">
    <compiler angle="radian" eulerseq="XYZ" />
    <option timestep="0.002" integrator="implicitfast" impratio="10" cone="elliptic" />

    <default>
        <geom rgba="0.7 0.7 0.7 1" />
        <default class="torso">
            <joint damping="0.01" frictionloss="0.01" armature="0.0" />
            <position kp="100" dampratio="1" />
        </default>
        <default class="wheel">
            <joint damping="0.01" frictionloss="0.01" armature="0.0" />
        </default>
        <default class="visual">
            <geom group="1" type="mesh" contype="4" conaffinity="4" />
        </default>
        <default class="rubber">
            <geom rgba="0.2 0.2 0.2 1" condim="3" friction="1 0.005 0.0001" priority="1"
                solimp="0.85 0.99 0.003" />
        </default>
    </default>

    <!-- <contact>
        <pair name="ball_floor" geom1="ball_geom" geom2="floor" condim="6" friction="1.0 1 0.01"
            solimp="0.85 0.99 0.006" />
    </contact> -->

    <asset>
        <mesh name="base_link" file="meshes/base_link.stl" scale="0.001 0.001 0.001" />
        <mesh name="wheel_base_link" file="meshes/wheel_base_link.stl" scale="0.001 0.001 0.001" />
        <mesh name="large_roller_link" file="meshes/large_roller_link.stl" scale="0.001 0.001 0.001" />
        <mesh name="small_roller_link" file="meshes/small_roller_link.stl" scale="0.001 0.001 0.001" />
        <mesh name="torso_link" file="meshes/torso_link.stl" scale="0.001 0.001 0.001" />
        <mesh name="left_shoulder_pitch_link" file="meshes/left_shoulder_pitch_link.stl"
            scale="0.001 0.001 0.001" />
        <mesh name="left_shoulder_roll_link" file="meshes/left_shoulder_roll_link.stl"
            scale="0.001 0.001 0.001" />
        <mesh name="left_shoulder_yaw_link" file="meshes/left_shoulder_yaw_link.stl"
            scale="0.001 0.001 0.001" />
        <mesh name="left_elbow_link" file="meshes/left_elbow_link.stl" scale="0.001 0.001 0.001" />
        <mesh name="right_shoulder_pitch_link" file="meshes/right_shoulder_pitch_link.stl"
            scale="0.001 0.001 0.001" />
        <mesh name="right_shoulder_roll_link" file="meshes/right_shoulder_roll_link.stl"
            scale="0.001 0.001 0.001" />
        <mesh name="right_shoulder_yaw_link" file="meshes/right_shoulder_yaw_link.stl"
            scale="0.001 0.001 0.001" />
        <mesh name="right_elbow_link" file="meshes/right_elbow_link.stl" scale="0.001 0.001 0.001" />
        <mesh name="neck_link" file="meshes/neck_link.stl" scale="0.001 0.001 0.001" />
        <mesh name="head_link" file="meshes/head_link.stl" scale="0.001 0.001 0.001" />
        <mesh name="ball_link" file="meshes/ball_link.stl" scale="0.001 0.001 0.001" />

        <!-- <texture name="grid" type="2d" builtin="checker" width="512" height="512"
            rgb1="0.8 0.8 0.8" rgb2="0.05 0.6 1" /> -->
        <texture name="grid_ball" type="2d" builtin="checker" width="512" height="512" rgb1="1 0 0"
            rgb2="0 1 0" />
        
        <!-- <material name="floor_mat" shininess="1" specular="1" texture="grid" texrepeat="20 20" /> -->
        <material name="ball_mat" texture="grid_ball" rgba="1 0 0 1" />
        <material name="body_mat" rgba="0.5 0.5 0.5 1" />
    </asset>

    <worldbody>
        <!-- <light directional="true" pos="-0.5 0.5 3" dir="0 0 -1" /> -->
        <!-- <geom name="floor" type="plane" pos="0 0 -0.12" size="5 5 0.1" material="floor_mat"
            rgba="1 1 1 1" contype="7" conaffinity="7" /> -->
        
        <body name="base_link" pos="0.0 0.0 0.0" euler="0.0 -0.0 0.0">
            <!-- <joint name="floating_base_joint" type="free" /> -->
            <!-- <freejoint /> -->
            <geom class="visual" name="base_geom" type="mesh" mesh="base_link" pos="0 0 0" euler="0 0 0" />
            <inertial mass="4.8833491952093615"
                pos="0.002877142611364894 0.0004304927756562858 0.26369851292018004"
                fullinertia="0.06026042259145148 0.059947763068358306 0.023961590336546337 -1.4986061024625154e-05 -0.0009871679684399044 -6.292837602434899e-05" />
            <body name="torso_link"
                pos="-3.583106902738109e-08 -1.526772356719164e-07 0.4400003721030327"
                euler="-1.0572366750157125e-12 9.49433738188822e-11 -1.224647802138242e-16">
                <geom class="visual" name="torso_geom" type="mesh" mesh="torso_link" pos="0 0 0" euler="0 0 0" />
                <inertial mass="3.2042605310287064"
                    pos="-1.6013326371601945e-05 -1.0744270105157319e-05 0.34937362535593"
                    fullinertia="0.06334146895523768 0.04663263530859074 0.02111375962377963 -1.1009513608811435e-05 0.00037934627063380277 5.775288224710326e-07" />
                <body name="left_shoulder_pitch_link"
                    pos="-2.00564608324183e-15 0.1589999999999997 0.39000000000000107"
                    euler="1.5707963267948968 1.2611068097459726e-16 -3.141592653589793">
                    <joint class="torso" name="left_shoulder_pitch_joint" type="hinge"
                        axis="0.0 0.0 1.0"
                        pos="-3.5794042900573486e-08 -3.7210286540555966e-07 1.5267682407266651e-07"
                        range="-3.1416 3.1416" />
                    <geom name="left_shoulder_pitch_geom" type="mesh"
                        mesh="left_shoulder_pitch_link" pos="0 0 0" euler="0 0 0" />
                    <inertial mass="0.5647196059165264"
                        pos="0.0017890372023412879 0.0007211685870429843 0.03799265025622402"
                        fullinertia="0.0005809283473076107 0.00045896665629299564 0.00032823418109896065 -8.650323768219957e-07 -1.756512815827473e-05 -4.147479150587224e-06" />
                    <body name="left_shoulder_roll_link"
                        pos="-4.882932649053471e-15 -1.0658141036401503e-14 0.05199999999999903"
                        euler="-2.5849394142282224e-26 -1.5707963267948963 0">
                        <joint class="torso" name="left_shoulder_roll_joint" type="hinge"
                            axis="0.0 0.0 1.0"
                            pos="1.5267682504219027e-07 -3.7210109092394093e-07 0.01800003579403801"
                            range="-3.6416 0.5" />
                        <geom name="left_shoulder_roll_geom" type="mesh"
                            mesh="left_shoulder_roll_link" pos="0 0 0" euler="0 0 0" />
                        <inertial mass="0.41969396888718885"
                            pos="1.9854515483463613e-05 -0.10241356863382063 -0.0010103945739280036"
                            fullinertia="0.0005955557660626536 0.00033614716314624344 0.0005708662221429325 -8.338255095488915e-08 -4.649806532489675e-08 -1.8286116531620543e-06" />
                        <body name="left_shoulder_yaw_link"
                            pos="-1.0658141036401502e-16 -0.13400000000000206 -1.614377034830916e-16"
                            euler="-1.5707963267948966 -1.5707963266999534 0">
                            <joint class="torso" name="left_shoulder_yaw_joint" type="hinge"
                                axis="0.0 0.0 1.0"
                                pos="3.5806760534673634e-08 1.526769668195918e-07 -3.721027980184195e-07" />
                            <geom name="left_shoulder_yaw_geom" type="mesh"
                                mesh="left_shoulder_yaw_link" pos="0 0 0" euler="0 0 0" />
                            <inertial mass="0.42120157414587867"
                                pos="-0.0009737648385027972 0.0023985839351739285 -0.11537172167139248"
                                fullinertia="0.0005277495063888407 0.000610291036234776 0.0002557216631582761 6.781354562296562e-07 -2.3200870240373922e-06 1.3529196450090723e-05" />
                            <body name="left_elbow_link"
                                pos="-6.705748508691956e-17 -7.105427357601002e-17 -0.12500000000000008"
                                euler="1.5707963267948966 -0.0 2.4651903288156597e-32">
                                <joint class="torso" name="left_elbow_joint" type="hinge"
                                    axis="0.0 0.0 1.0"
                                    pos="3.580676059870778e-08 -3.7210281693918537e-07 0.01799984732290097"
                                    range="0.0 2.65" />
                                <geom name="left_elbow_geom" type="mesh" mesh="left_elbow_link"
                                    pos="0 0 0" euler="0 0 0" />
                                <inertial mass="0.1558676529430366"
                                    pos="1.895082812576374e-05 -0.16594223580246156 -0.00021726971288407525"
                                    fullinertia="0.0017964862899183462 6.465951882236173e-05 0.0017825833478305741 -5.828593428573483e-07 -1.341909303522208e-09 6.551929599814123e-06" />
                                <site name="left_wrist" pos="0 -0.30 0" />
                            </body>
                        </body>
                    </body>
                </body>
                <body name="right_shoulder_pitch_link"
                    pos="2.3323010359219566e-15 -0.15900000000000222 0.38999999999999935"
                    euler="1.5707963267948966 1.2924697071140994e-26 -7.771561172521638e-16">
                    <joint class="torso" name="right_shoulder_pitch_joint" type="hinge"
                        axis="0.0 0.0 1.0"
                        pos="3.579403884870565e-08 -3.7210319991575603e-07 -1.5267682562697864e-07" />
                    <geom name="right_shoulder_pitch_geom" type="mesh"
                        mesh="right_shoulder_pitch_link" pos="0 0 0" euler="0 0 0" />
                    <inertial mass="0.5647195174488359"
                        pos="-0.0017890372261850013 0.0007262942975002131 0.03802171905559493"
                        fullinertia="0.0005813834106877971 0.00045945210829132746 0.00032820377192648487 9.281419443609914e-07 1.792308601114821e-05 -4.1041701529296065e-06" />
                    <body name="right_shoulder_roll_link"
                        pos="2.052289396673563e-15 9.805489753489383e-15 0.051999999999945014"
                        euler="3.877409121342313e-26 1.570796326794896 0">
                        <joint class="torso" name="right_shoulder_roll_joint" type="hinge"
                            axis="0.0 0.0 1.0"
                            pos="1.526767706183278e-07 -3.721015558158585e-07 0.018000035794036803"
                            range="-0.5 3.6416" />
                        <geom name="right_shoulder_roll_geom" type="mesh"
                            mesh="right_shoulder_roll_link" pos="0 0 0" euler="0 0 0" />
                        <inertial mass="0.41969396888718835"
                            pos="1.9855094994873372e-05 -0.10241356863382119 -0.001010394573925032"
                            fullinertia="0.0005955557660626807 0.0003361471631365829 0.0005708662221333544 -8.339147097248404e-08 -4.649455206934536e-08 -1.828611653176317e-06" />
                        <body name="right_shoulder_yaw_link"
                            pos="1.0658141036401502e-16 -0.13400000000000162 2.6807810079803697e-15"
                            euler="-1.5707963267948966 -1.5707963266999532 0">
                            <joint class="torso" name="right_shoulder_yaw_joint" type="hinge"
                                axis="0.0 0.0 1.0"
                                pos="3.5806756213066426e-08 1.5267691216886357e-07 -3.721032628687999e-07" />
                            <geom name="right_shoulder_yaw_geom" type="mesh"
                                mesh="right_shoulder_yaw_link" pos="0 0 0" euler="0 0 0" />
                            <inertial mass="0.31888998976294225"
                                pos="-0.0011863258736410478 -0.0005085260861692219 -0.11226734788502574"
                                fullinertia="0.00046404368059872747 0.0005614990403560987 0.00020351701899910818 -8.892445773084024e-07 -3.4394261033964377e-06 -5.713436326940516e-06" />
                            <body name="right_elbow_link"
                                pos="-4.476280288003964e-17 1.9895196601282807e-15 -0.12499999999999993"
                                euler="1.5707963267948966 1.2246467991473515e-16 3.141592653589793">
                                <joint class="torso" name="right_elbow_joint" type="hinge"
                                    axis="0.0 0.0 1.0"
                                    pos="-3.580675622827567e-08 -3.72103243839333e-07 0.01800015267704233"
                                    range="-2.65 0.0" />
                                <geom name="right_elbow_geom" type="mesh" mesh="right_elbow_link"
                                    pos="0 0 0" euler="0 0 0" />
                                <inertial mass="0.15586791529929014"
                                    pos="-5.626475324908146e-05 -0.16594235540000968 -0.00021726961129907342"
                                    fullinertia="0.001796485962998362 6.46591441813976e-05 0.0017825826442405615 2.3653024226103953e-07 1.2047957958458172e-09 6.5519346690109845e-06" />
                                <site name="right_wrist" pos="0 -0.30 0" />
                            </body>
                        </body>
                    </body>
                </body>
                <body name="neck_link"
                    pos="-2.0738965930591334e-15 -8.215650382226159e-16 0.4740000000000006"
                    euler="6.050651873526047e-16 -9.494337381888174e-11 4.9303806576312953e-32">
                    <joint class="torso" name="neck_joint" type="hinge"
                        axis="0.0 0.0 1.0"
                        pos="3.578606780966733e-08 1.5267673565049155e-07 -3.7210303283058933e-07"
                        range="-3.1416 3.1416" />
                    <geom class="visual" name="neck_geom" type="mesh" mesh="neck_link" pos="0 0 0" euler="0 0 0" />
                    <inertial mass="0.6024876453871971"
                        pos="-0.0006047734094668232 0.005373207603459829 0.04072295517902659"
                        fullinertia="0.0005387498816373792 0.0006647047803757507 0.0003746653098801926 -1.2150198739273867e-06 1.964598514418685e-06 -6.496444910251773e-05" />
                    <body name="head_link"
                        pos="-1.3529108389143118e-15 -2.022304747978116e-15 0.05199999999999918"
                        euler="1.5707963267948966 -0.0 0.0">
                        <joint class="torso" name="head_joint" type="hinge"
                            axis="0.0 0.0 1.0"
                            pos="3.5786069164782536e-08 -3.7210305107280217e-07 0.01799984732331727"
                            range="-1.5708 1.5708" />
                        <geom class="visual" name="head_geom" type="mesh" mesh="head_link" pos="0 0 0"
                            euler="0 0 0" />
                        <inertial mass="0.41566857186457795"
                            pos="0.05151482658154114 0.09721120269673268 0.0011638699723890307"
                            fullinertia="0.0016807421181515014 0.0009385707505779181 0.0011870976231925469 -0.0004216047607379162 9.920403095927295e-06 1.0995743528604151e-05" />
                    </body>
                </body>
            </body>
            <body name="wheel_base_1_link"
                pos="0.11667258306929952 -1.5267637062166273e-07 0.11667299099912871"
                euler="0.7853981634093242 2.9712693584874207e-15 -1.570796326794905">
                <joint class="wheel" name="wheel_base_1_joint" type="hinge"
                    axis="-3.849605452655475e-15 -1.1871503780014336e-11 -1.0000003094489534"
                    pos="-1.5267637051195055e-07 3.0117944105866046e-07 0.02850035747255655" />
                <geom name="wheel_base_1_geom" type="mesh" mesh="wheel_base_link" pos="0 0 0"
                    euler="0 0 0" />
                <inertial mass="0.17443341496039455"
                    pos="9.782089798802018e-10 -1.8336303406630422e-09 0.0034060367436682627"
                    fullinertia="8.975302268151669e-05 8.97530339940819e-05 0.00015994906614931356 -4.444708393019034e-12 6.915951726955189e-13 -1.1877841849731834e-12" />
                <body name="small_roller_1_1_link"
                    pos="-3.0198066269804257e-15 2.7355895326763858e-15 6.039642053081058e-16"
                    euler="1.1546319456101664e-14 -2.275957200481578e-14 -1.256637061435896">
                    <joint name="small_roller_1_1_joint" type="hinge"
                        axis="1.0000006581452665 -2.0792984734008257e-07 1.126970738951627e-11"
                        pos="0.013499784587129018 0.04099986046855231 -2.884499478425425e-07" />
                    <geom name="small_roller_1_1_geom" type="mesh" mesh="small_roller_link"
                        pos="0 0 0" euler="0 0 0" />
                    <inertial mass="0.014279541547129664"
                        pos="2.0209528495129803e-16 0.0410000000000004 -1.7048255168683468e-13"
                        fullinertia="5.657078922023473e-07 9.46139894853657e-07 9.461398910240957e-07 -1.5365707058785042e-20 1.266843651737213e-19 7.085959999374256e-20" />
                </body>
                <body name="large_roller_1_1_link"
                    pos="-3.1086244689504383e-15 2.842170943040401e-15 4.0856495297407826e-16"
                    euler="1.1796119636642304e-14 -2.2148949341271895e-14 -1.256637061435897">
                    <joint name="large_roller_1_1_joint" type="hinge"
                        axis="-0.8090170798023407 -0.5877852304499527 -6.9542149816470555e-12"
                        pos="-0.015231071016206887 0.033432826089070014 -2.8845024358480076e-07" />
                    <geom name="large_roller_1_1_geom" type="mesh" mesh="large_roller_link"
                        pos="0 0 0" euler="0 0 0" />
                    <inertial mass="0.026209434773783076"
                        pos="-0.02116026908254156 0.02912461179751499 1.214306433183765e-17"
                        fullinertia="2.946851573186859e-06 2.7942679958917657e-06 2.6236743710133415e-06 2.3480198194164277e-07 1.15619997300212e-19 1.2297859602948373e-19" />
                </body>
                <body name="small_roller_1_2_link"
                    pos="-3.4994229736184934e-15 3.0908609005564358e-15 5.862006369141034e-16"
                    euler="-1.4710455076283365e-14 -1.723586303551631e-14 2.4677420861424398e-14">
                    <joint name="small_roller_1_2_joint" type="hinge"
                        axis="1.0000000000000022 -1.8261423354743834e-14 -1.703514676670854e-14"
                        pos="0.01349984732363359 0.04099976656585802 -2.8845043547123805e-07" />
                    <geom name="small_roller_1_2_geom" type="mesh" mesh="small_roller_link"
                        pos="0 0 0" euler="0 0 0" />
                    <inertial mass="0.014279541547129664"
                        pos="9.751927101037905e-17 0.04100000000000059 -1.706690344605022e-13"
                        fullinertia="5.657078922020044e-07 9.461398948538387e-07 9.461398910239878e-07 -2.1638038220087864e-20 1.2157242104416778e-19 -5.569241628197025e-20" />
                </body>
                <body name="large_roller_1_2_link"
                    pos="-3.0375701953744282e-15 3.0908609005564358e-15 4.796192265500883e-16"
                    euler="-1.676436767183988e-14 -1.8230663804143147e-14 2.9544707483344036e-14">
                    <joint name="large_roller_1_2_joint" type="hinge"
                        axis="-0.8090170000000165 -0.5877853402884259 6.9828587356823846e-12"
                        pos="-0.01523115267636694 0.03343230979360008 -2.8845034504010325e-07" />
                    <geom name="large_roller_1_2_geom" type="mesh" mesh="large_roller_link"
                        pos="0 0 0" euler="0 0 0" />
                    <inertial mass="0.026209434773783076"
                        pos="-0.02116026908254151 0.029124611797515076 -1.3183898417423734e-16"
                        fullinertia="2.946851573186553e-06 2.7942679958915773e-06 2.623674371013073e-06 2.3480198194153151e-07 1.7407850555055957e-19 -1.3129010682441655e-19" />
                </body>
                <body name="small_roller_1_3_link"
                    pos="-3.4106051316484808e-15 3.161915174132446e-15 7.815998892481309e-16"
                    euler="-2.314815006343456e-14 1.1157741397482831e-14 1.25663706143593">
                    <joint name="small_roller_1_3_joint" type="hinge"
                        axis="1.000000658145264 2.0792981766937224e-07 -1.1280920642064984e-11"
                        pos="0.013500342316723368 0.040999653768223225 4.1865653009967585e-07" />
                    <geom name="small_roller_1_3_geom" type="mesh" mesh="small_roller_link"
                        pos="0 0 0" euler="0 0 0" />
                    <inertial mass="0.014279541547129664"
                        pos="2.3765711620882257e-16 0.04100000000000042 -1.708173533176982e-13"
                        fullinertia="5.65707892202209e-07 9.461398948537118e-07 9.461398910241246e-07 9.065899513581183e-20 7.702705864093794e-20 -1.0466150854510949e-19" />
                </body>
                <body name="large_roller_1_3_link"
                    pos="-3.4283687000424833e-15 2.948752353404416e-15 4.796192265500883e-16"
                    euler="-2.2815083156046967e-14 1.0547118733938978e-14 1.2566370614359321">
                    <joint name="large_roller_1_3_joint" type="hinge"
                        axis="-0.8090176490437473 -0.5877854709217778 1.1270429034482277e-11"
                        pos="-0.015231409343215218 0.03343270120780569 -2.8844989906871843e-07" />
                    <geom name="large_roller_1_3_geom" type="mesh" mesh="large_roller_link"
                        pos="0 0 0" euler="0 0 0" />
                    <inertial mass="0.026209434773783076"
                        pos="-0.021160269082541365 0.02912461179751489 -1.717376241217039e-16"
                        fullinertia="2.946851573186869e-06 2.794267995891842e-06 2.6236743710135655e-06 2.3480198194168295e-07 -2.0117032497289633e-20 -2.3759274170483125e-19" />
                </body>
                <body name="small_roller_1_4_link"
                    pos="-2.913225216616411e-15 2.806643806252396e-15 8.348905944301384e-16"
                    euler="3.608224830031768e-15 2.6589841439772606e-14 2.513274122871849">
                    <joint name="small_roller_1_4_joint" type="hinge"
                        axis="1.0000000562734999 -6.788392389878162e-08 -6.954103959344593e-12"
                        pos="0.013499990551012982 0.041000400746199366 -2.8844964950966445e-07" />
                    <geom name="small_roller_1_4_geom" type="mesh" mesh="small_roller_link"
                        pos="0 0 0" euler="0 0 0" />
                    <inertial mass="0.014279541547129664"
                        pos="0.0 0.04100000000000034 -1.7066556501355024e-13"
                        fullinertia="5.657078922023475e-07 9.461398948538035e-07 9.46139891024191e-07 -5.995405079784345e-20 -1.3377826610697606e-19 -2.3081647812679684e-20" />
                </body>
                <body name="large_roller_1_4_link"
                    pos="-2.8244073746463984e-15 2.877698079828406e-15 4.440920897620833e-16"
                    euler="1.27675647831893e-15 2.503552920529732e-14 2.5132741228718496">
                    <joint name="large_roller_1_4_joint" type="hinge"
                        axis="-0.8090169943749577 -0.5877852522924637 -1.767892119925773e-14"
                        pos="-0.015230812557942158 0.033432514336212985 -2.8844952187565e-07" />
                    <geom name="large_roller_1_4_geom" type="mesh" mesh="large_roller_link"
                        pos="0 0 0" euler="0 0 0" />
                    <inertial mass="0.026209434773783076"
                        pos="-0.021160269082541643 0.029124611797514986 7.632783294297951e-17"
                        fullinertia="2.946851573186855e-06 2.794267995891634e-06 2.623674371013281e-06 2.3480198194138103e-07 -2.250990057328303e-19 -7.263307522705625e-20" />
                </body>
                <body name="small_roller_1_5_link"
                    pos="-6.572520305780927e-16 7.460698725481052e-16 6.927820472781184e-16"
                    euler="7.6605388699136e-15 2.3869795029440838e-15 -2.5132741228718336">
                    <joint name="small_roller_1_5_joint" type="hinge"
                        axis="1.0000000562734974 6.788391571088681e-08 6.9809158453892906e-12"
                        pos="0.013499530057211485 0.04100000206197482 4.186573197874355e-07" />
                    <geom name="small_roller_1_5_geom" type="mesh" mesh="small_roller_link"
                        pos="0 0 0" euler="0 0 0" />
                    <inertial mass="0.014279541547129664"
                        pos="1.9949319973733282e-16 0.0410000000000005 -1.704435204086252e-13"
                        fullinertia="5.657078922021408e-07 9.461398948538084e-07 9.461398910240963e-07 3.417248546579068e-20 -3.917527381051139e-20 1.1117307432712692e-19" />
                </body>
                <body name="large_roller_1_5_link"
                    pos="-3.0730973321624333e-15 2.486899575160351e-15 4.618556581560858e-16"
                    euler="2.4757973449141013e-14 4.8294701571194136e-15 -2.51327412287181">
                    <joint name="large_roller_1_5_joint" type="hinge"
                        axis="-0.8090174046075778 -0.5877858073593035 -1.1280809619762522e-11"
                        pos="-0.015230860534281947 0.033431975769724544 -2.884497349656123e-07" />
                    <geom name="large_roller_1_5_geom" type="mesh" mesh="large_roller_link"
                        pos="0 0 0" euler="0 0 0" />
                    <inertial mass="0.026209434773783076"
                        pos="-0.021160269082541355 0.029124611797514955 1.7520707107365752e-16"
                        fullinertia="2.946851573186838e-06 2.7942679958918534e-06 2.6236743710135333e-06 2.3480198194158294e-07 -1.1943164556285635e-19 1.7279472123987727e-19" />
                </body>
            </body>
            <body name="wheel_base_2_link"
                pos="-0.058336345275753425 0.10104129921129165 0.11667299099694427"
                euler="-0.36136712390671116 0.7137243789368602 -1.5707963267948977">
                <joint class="wheel" name="wheel_base_2_joint" type="hinge"
                    axis="4.725946980976836e-07 3.230029291811931e-07 -0.9999997498207982"
                    pos="-5.431710601976752e-07 1.736948323019516e-08 0.02850016234091567" />
                <geom name="wheel_base_2_geom" type="mesh" mesh="wheel_base_link" pos="0 0 0"
                    euler="0 0 0" />
                <inertial mass="0.17443341496039455"
                    pos="9.782089884207562e-10 -1.8336302725751458e-09 0.003406036743668209"
                    fullinertia="8.975302268151439e-05 8.975303399407842e-05 0.0001599490661493084 -4.444707880284053e-12 6.915941072865167e-13 -1.1877845813846027e-12" />
                <body name="small_roller_2_1_link"
                    pos="1.0658141036401502e-16 1.127986593019159e-15 -2.966521342809281e-15"
                    euler="-1.9206858326015183e-14 7.771561172376091e-15 1.2566370614358988">
                    <joint name="small_roller_2_1_joint" type="hinge"
                        axis="1.0000002364239295 -9.590714644680531e-08 -2.6153408516638166e-07"
                        pos="0.0134996898250769 0.04100013591799676 3.818929015641376e-07" />
                    <geom name="small_roller_2_1_geom" type="mesh" mesh="small_roller_link"
                        pos="0 0 0" euler="0 0 0" />
                    <inertial mass="0.014279541547129664"
                        pos="1.97758476261356e-16 0.04099999999999995 -1.705788288397514e-13"
                        fullinertia="5.657078922022275e-07 9.461398948537933e-07 9.461398910241605e-07 4.732796592783403e-20 7.358598729271734e-21 9.68793933422106e-21" />
                </body>
                <body name="large_roller_2_1_link"
                    pos="1.4210854715202004e-16 1.3766765505351941e-15 -3.5171919630233582e-15"
                    euler="-1.9040324872321387e-14 7.716050021144817e-15 1.2566370614359004">
                    <joint name="large_roller_2_1_joint" type="hinge"
                        axis="-0.809016871509944 -0.5877857504918215 -1.567990723927437e-07"
                        pos="-0.015231560824107804 0.03343207480824493 -3.379099790604134e-08" />
                    <geom name="large_roller_2_1_geom" type="mesh" mesh="large_roller_link"
                        pos="0 0 0" euler="0 0 0" />
                    <inertial mass="0.026209434773783076"
                        pos="-0.021160269082541185 0.02912461179751466 1.0408340855860843e-16"
                        fullinertia="2.946851573186785e-06 2.794267995891708e-06 2.623674371013368e-06 2.3480198194165092e-07 -1.2641966737770433e-19 9.507944832929521e-20" />
                </body>
                <body name="small_roller_2_2_link"
                    pos="3.907985046680551e-16 1.2079226507921704e-15 -3.090866321567298e-15"
                    euler="1.9984014443252774e-15 2.0983215165415408e-14 2.5132741228718185">
                    <joint name="small_roller_2_2_joint" type="hinge"
                        axis="1.0000000742549089 -7.518924202698507e-08 4.087163663069049e-07"
                        pos="0.013500189946872928 0.041000020891661076 1.687224653046382e-07" />
                    <geom name="small_roller_2_2_geom" type="mesh" mesh="small_roller_link"
                        pos="0 0 0" euler="0 0 0" />
                    <inertial mass="0.014279541547129664"
                        pos="1.3183898417423734e-16 0.041 -1.7051637879461623e-13"
                        fullinertia="5.657078922022345e-07 9.461398948537263e-07 9.461398910241168e-07 8.316804750853161e-20 -6.961552035246281e-21 7.369186641112413e-20" />
                </body>
                <body name="large_roller_2_2_link"
                    pos="1.7763568394002506e-16 1.2878587085651815e-15 -3.2329748687193183e-15"
                    euler="-1.9984014443252743e-15 1.787459069646494e-14 2.5132741228718203">
                    <joint name="large_roller_2_2_joint" type="hinge"
                        axis="-0.8090171574025656 -0.5877854640812659 -1.997952233656619e-07"
                        pos="-0.015231061791618185 0.03343204874078224 -8.224149732408148e-08" />
                    <geom name="large_roller_2_2_geom" type="mesh" mesh="large_roller_link"
                        pos="0 0 0" euler="0 0 0" />
                    <inertial mass="0.026209434773783076"
                        pos="-0.02116026908254131 0.029124611797514702 3.0357660829594124e-17"
                        fullinertia="2.946851573186677e-06 2.7942679958917183e-06 2.6236743710135376e-06 2.34801981941566e-07 2.3081647812679684e-20 1.1689054672109345e-19" />
                </body>
                <body name="small_roller_2_3_link"
                    pos="4.973799150320702e-16 1.3855583347321954e-15 -2.9842849112032834e-15"
                    euler="1.86517468137026e-14 5.329070518200755e-15 -2.5132741228718483">
                    <joint name="small_roller_2_3_joint" type="hinge"
                        axis="1.000000253524334 -9.662740239890777e-08 -4.976947649559804e-07"
                        pos="0.013499701564157664 0.04099983181547982 2.0188187049635306e-07" />
                    <geom name="small_roller_2_3_geom" type="mesh" mesh="small_roller_link"
                        pos="0 0 0" euler="0 0 0" />
                    <inertial mass="0.014279541547129664"
                        pos="1.7694179454963432e-16 0.04099999999999998 -1.7066383029007426e-13"
                        fullinertia="5.657078922020671e-07 9.461398948537089e-07 9.461398910241339e-07 -3.864587821847745e-21 4.8757334026325663e-20 -3.210784265685832e-20" />
                </body>
                <body name="large_roller_2_3_link"
                    pos="1.0658141036401502e-16 1.305622276959184e-15 -3.4461376894473485e-15"
                    euler="2.0150547896946538e-14 4.88498130835068e-15 -2.5132741228718465">
                    <joint name="large_roller_2_3_joint" type="hinge"
                        axis="-0.8090172420187354 -0.5877853136684558 -2.6153408383411403e-07"
                        pos="-0.015230891455207337 0.033431764641166734 2.2849469509360343e-07" />
                    <geom name="large_roller_2_3_geom" type="mesh" mesh="large_roller_link"
                        pos="0 0 0" euler="0 0 0" />
                    <inertial mass="0.026209434773783076"
                        pos="-0.021160269082541136 0.02912461179751466 -8.847089727481716e-17"
                        fullinertia="2.9468515731866235e-06 2.794267995891917e-06 2.6236743710136417e-06 2.348019819416389e-07 1.4823076576950256e-20 -4.740737526663912e-20" />
                </body>
                <body name="small_roller_2_4_link"
                    pos="3.552713678800501e-17 1.4477308241112042e-15 -2.966521342809281e-15"
                    euler="1.110223024625154e-14 -1.6840695504782815e-14 -1.256637061435927">
                    <joint name="small_roller_2_4_joint" type="hinge"
                        axis="1.0000001934343536 4.7526997099672785e-07 -1.5679907352378342e-07"
                        pos="0.013500183812869415 0.041000319270501344 8.816299103264758e-08" />
                    <geom name="small_roller_2_4_geom" type="mesh" mesh="small_roller_link"
                        pos="0 0 0" euler="0 0 0" />
                    <inertial mass="0.014279541547129664"
                        pos="2.1272046624165597e-16 0.04099999999999991 -1.7069679003611782e-13"
                        fullinertia="5.657078922022326e-07 9.461398948537333e-07 9.461398910242039e-07 6.126430488812744e-20 1.1921326988114235e-20 -5.685708658444491e-20" />
                </body>
                <body name="large_roller_2_4_link"
                    pos="1.2434497875801754e-16 1.1723955140041654e-15 -3.357319847477336e-15"
                    euler="1.0436096431476435e-14 -1.730560139634457e-14 -1.256637061435925">
                    <joint name="large_roller_2_4_joint" type="hinge"
                        axis="-0.8090170986435639 -0.587785235109032 4.087163661958826e-07"
                        pos="-0.01523159923466527 0.0334323879964948 -2.877647487450896e-07" />
                    <geom name="large_roller_2_4_geom" type="mesh" mesh="large_roller_link"
                        pos="0 0 0" euler="0 0 0" />
                    <inertial mass="0.026209434773783076"
                        pos="-0.021160269082541202 0.029124611797514598 -8.500145032286355e-17"
                        fullinertia="2.9468515731868484e-06 2.7942679958917314e-06 2.6236743710135596e-06 2.3480198194162604e-07 -1.5385559393486315e-21 -9.169131654027801e-20" />
                </body>
                <body name="small_roller_2_5_link"
                    pos="-3.1974423109204507e-16 5.950795411990839e-16 -6.572574515889551e-16"
                    euler="5.273559366969486e-16 -3.996802888650558e-15 -2.1649348980190525e-15">
                    <joint name="small_roller_2_5_joint" type="hinge"
                        axis="1.000000256378441 7.551549194295681e-08 -1.9979521304058778e-07"
                        pos="0.013500233550216727 0.04100047554225823 -2.482446298732177e-07" />
                    <geom name="small_roller_2_5_geom" type="mesh" mesh="small_roller_link"
                        pos="0 0 0" euler="0 0 0" />
                    <inertial mass="0.014279541547129664"
                        pos="1.2923689896027213e-16 0.04100000000000006 -1.7068638169526196e-13"
                        fullinertia="5.657078922021085e-07 9.461398948537699e-07 9.461398910241437e-07 2.6205081805679917e-21 -7.109782801015783e-20 -3.943997160652836e-20" />
                </body>
                <body name="large_roller_2_5_link"
                    pos="2.842170943040401e-16 1.438849039914203e-15 -3.5171919630233582e-15"
                    euler="-1.3211653993039328e-14 -1.620925615952723e-14 -4.69069227904127e-15">
                    <joint name="large_roller_2_5_joint" type="hinge"
                        axis="-0.8090172562766131 -0.5877853231371206 -4.976947627355344e-07"
                        pos="-0.015231144983101784 0.033432553673453706 1.5534571670423446e-07" />
                    <geom name="large_roller_2_5_geom" type="mesh" mesh="large_roller_link"
                        pos="0 0 0" euler="0 0 0" />
                    <inertial mass="0.026209434773783076"
                        pos="-0.021160269082541205 0.029124611797514674 -8.673617379884035e-18"
                        fullinertia="2.9468515731866294e-06 2.7942679958916645e-06 2.623674371013518e-06 2.348019819414976e-07 -1.207021949837378e-20 -1.2006692027329707e-19" />
                </body>
            </body>
            <body name="wheel_base_3_link"
                pos="-0.05833634527298409 -0.10104160456831825 0.11667299099715839"
                euler="-0.36136712388876596 -0.7137243789468081 -1.5707963267948961">
                <joint class="wheel" name="wheel_base_3_joint" type="hinge"
                    axis="-4.7260400326543106e-07 3.229849846464461e-07 -0.9999997498208015"
                    pos="3.123429699481567e-07 -5.330895679923897e-08 0.02850034933201138" />
                <geom name="wheel_base_3_geom" type="mesh" mesh="wheel_base_link" pos="0 0 0"
                    euler="0 0 0" />
                <inertial mass="0.17443341496039455"
                    pos="9.782088687248364e-10 -1.8336302814656036e-09 0.0034060367436682193"
                    fullinertia="8.975302268151694e-05 8.97530339940842e-05 0.0001599490661493146 -4.4447060608572824e-12 6.915937345920199e-13 -1.1877842798408735e-12" />
                <body name="small_roller_3_1_link"
                    pos="-6.927791673660977e-16 6.217248937900877e-17 2.6645344120674284e-15"
                    euler="1.3933298959045738e-14 -2.498001805406601e-15 -2.5132741228718474">
                    <joint name="small_roller_3_1_joint" type="hinge"
                        axis="1.0000000742549116 7.519278727441403e-08 -4.0869826972711465e-07"
                        pos="0.013499885202024667 0.0409995135083474 -1.938667854046311e-07" />
                    <geom name="small_roller_3_1_geom" type="mesh" mesh="small_roller_link"
                        pos="0 0 0" euler="0 0 0" />
                    <inertial mass="0.014279541547129664"
                        pos="-1.5612511283791264e-17 0.04100000000000013 -1.706690344605022e-13"
                        fullinertia="5.657078922022739e-07 9.461398948536572e-07 9.461398910239891e-07 -1.0339095912422804e-19 7.146840492458159e-20 -5.1880768019325896e-20" />
                </body>
                <body name="large_roller_3_1_link"
                    pos="-8.171241461241152e-16 -8.881784197001253e-18 2.2026816338233633e-15"
                    euler="1.4155343563970746e-14 -2.4424906541753397e-15 -2.5132741228718456">
                    <joint name="large_roller_3_1_joint" type="hinge"
                        axis="-0.8090174302212284 -0.5877849814917129 1.5677912500872138e-07"
                        pos="-0.015231165187498046 0.033431785942365205 -1.5160878235470632e-07" />
                    <geom name="large_roller_3_1_geom" type="mesh" mesh="large_roller_link"
                        pos="0 0 0" euler="0 0 0" />
                    <inertial mass="0.026209434773783076"
                        pos="-0.021160269082541504 0.02912461179751487 -5.898059818321144e-17"
                        fullinertia="2.9468515731866675e-06 2.7942679958916205e-06 2.62367437101296e-06 2.3480198194137828e-07 -1.5183065579533334e-19 -2.964615315390051e-21" />
                </body>
                <body name="small_roller_3_2_link"
                    pos="-7.638334409421077e-16 2.042810365310288e-16 2.5224258649154083e-15"
                    euler="7.771561172376114e-16 -1.426636586643325e-14 -1.2566370614359277">
                    <joint name="small_roller_3_2_joint" type="hinge"
                        axis="1.0000002364239307 9.591069438652511e-08 2.615482672663205e-07"
                        pos="0.013499822193486116 0.04099968493760848 -3.031536473241392e-07" />
                    <geom name="small_roller_3_2_geom" type="mesh" mesh="small_roller_link"
                        pos="0 0 0" euler="0 0 0" />
                    <inertial mass="0.014279541547129664"
                        pos="2.5673907444456745e-16 0.041000000000000404 -1.707661789751569e-13"
                        fullinertia="5.657078922017489e-07 9.461398948537371e-07 9.461398910237844e-07 1.1765817032954266e-19 3.9148804030909694e-20 -1.3054895299556904e-19" />
                </body>
                <body name="large_roller_3_2_link"
                    pos="-6.217248937900877e-16 1.2434497875801754e-16 2.2026816338233633e-15"
                    euler="8.881784197001262e-16 -1.465494392505204e-14 -1.2566370614359255">
                    <joint name="large_roller_3_2_joint" type="hinge"
                        axis="-0.8090171426822029 -0.5877854794864168 4.976917664101244e-07"
                        pos="-0.015231229196256035 0.033432494157608426 5.565440292093493e-07" />
                    <geom name="large_roller_3_2_geom" type="mesh" mesh="large_roller_link"
                        pos="0 0 0" euler="0 0 0" />
                    <inertial mass="0.026209434773783076"
                        pos="-0.021160269082541136 0.02912461179751492 -8.933825901280557e-17"
                        fullinertia="2.9468515731865777e-06 2.7942679958919178e-06 2.6236743710131763e-06 2.3480198194162254e-07 -8.512681119905718e-20 -6.6280328122649e-20" />
                </body>
                <body name="small_roller_3_3_link"
                    pos="-1.1013412404281553e-15 2.3980817331903383e-16 2.646770843673426e-15"
                    euler="-1.1962653090336093e-14 -5.551115123125788e-15 -6.966649479522864e-15">
                    <joint name="small_roller_3_3_joint" type="hinge"
                        axis="1.0000002563784454 -7.551196637423097e-08 1.9978589271829605e-07"
                        pos="0.01349970369295549 0.0410002922103246 2.3679750350185172e-07" />
                    <geom name="small_roller_3_3_geom" type="mesh" mesh="small_roller_link"
                        pos="0 0 0" euler="0 0 0" />
                    <inertial mass="0.014279541547129664"
                        pos="1.43982048506075e-16 0.04100000000000001 -1.7067857543962006e-13"
                        fullinertia="5.65707892202354e-07 9.461398948538058e-07 9.461398910241351e-07 3.602537003790946e-20 -9.132073962585426e-20 -5.346895479542771e-21" />
                </body>
                <body name="large_roller_3_3_link"
                    pos="-1.0302869668521452e-15 4.4408920985006264e-17 2.1849180654293608e-15"
                    euler="-1.2823075934420577e-14 -5.218048215738231e-15 -5.301314942585118e-15">
                    <joint name="large_roller_3_3_joint" type="hinge"
                        axis="-0.8090170102512271 -0.5877853567706498 -4.0869826928302544e-07"
                        pos="-0.01523096518659631 0.033432491821387134 3.189824679377534e-07" />
                    <geom name="large_roller_3_3_geom" type="mesh" mesh="large_roller_link"
                        pos="0 0 0" euler="0 0 0" />
                    <inertial mass="0.026209434773783076"
                        pos="-0.02116026908254139 0.029124611797514646 1.3877787807814457e-17"
                        fullinertia="2.946851573186953e-06 2.794267995891569e-06 2.6236743710132534e-06 2.3480198194158316e-07 -1.2705494208814505e-19 -5.304543832180056e-20" />
                </body>
                <body name="small_roller_3_4_link"
                    pos="-1.0302869668521452e-15 7.993605777301127e-17 2.753352254037441e-15"
                    euler="-1.01585406753202e-14 1.1046719095020304e-14 1.2566370614358995">
                    <joint name="small_roller_3_4_joint" type="hinge"
                        axis="1.0000001934343532 -4.7526642568684885e-07 1.5677912434952646e-07"
                        pos="0.013499866557636433 0.041000308247842746 -2.0371409078720482e-07" />
                    <geom name="small_roller_3_4_geom" type="mesh" mesh="small_roller_link"
                        pos="0 0 0" euler="0 0 0" />
                    <inertial mass="0.014279541547129664"
                        pos="3.5128150388530344e-17 0.041000000000000265 -1.7061005386231898e-13"
                        fullinertia="5.657078922019854e-07 9.461398948537461e-07 9.461398910239977e-07 -6.37921688400895e-20 -5.3826296820050617e-20 2.9010878443459787e-20" />
                </body>
                <body name="large_roller_3_4_link"
                    pos="-1.0835776720341528e-15 -1.687538997430238e-16 2.0783366550653457e-15"
                    euler="-9.992007221626415e-15 1.0651202142497566e-14 1.2566370614359026">
                    <joint name="large_roller_3_4_joint" type="hinge"
                        axis="-0.8090171292710321 -0.5877854688523584 2.6154826804347664e-07"
                        pos="-0.015231365877860302 0.033431697626514295 -2.1595697446974427e-07" />
                    <geom name="large_roller_3_4_geom" type="mesh" mesh="large_roller_link"
                        pos="0 0 0" euler="0 0 0" />
                    <inertial mass="0.026209434773783076"
                        pos="-0.021160269082541344 0.02912461179751496 3.122502256758253e-17"
                        fullinertia="2.9468515731864164e-06 2.794267995891714e-06 2.62367437101311e-06 2.3480198194143482e-07 -5.296602898299547e-20 -3.875175733688424e-20" />
                </body>
                <body name="small_roller_3_5_link"
                    pos="-4.618527782440651e-16 -3.6415315207705137e-16 1.0835768250012055e-15"
                    euler="2.7616797737550844e-15 4.773959005888172e-15 2.513274122871822">
                    <joint name="small_roller_3_5_joint" type="hinge"
                        axis="1.0000002535243393 9.663094807654815e-08 4.976917569177175e-07"
                        pos="0.013499646395967539 0.0409995749342801 5.9456419945411176e-08" />
                    <geom name="small_roller_3_5_geom" type="mesh" mesh="small_roller_link"
                        pos="0 0 0" euler="0 0 0" />
                    <inertial mass="0.014279541547129664"
                        pos="3.469446951953614e-16 0.041000000000000064 -1.7060398233015306e-13"
                        fullinertia="5.65707892202278e-07 9.46139894853791e-07 9.46139891024063e-07 6.711412618010245e-20 3.271664758769735e-20 3.0043199847925965e-20" />
                </body>
                <body name="large_roller_3_5_link"
                    pos="-9.414691248821328e-16 9.769962616701378e-17 2.255972339005371e-15"
                    euler="4.954370247389766e-15 1.0935696792557775e-14 2.5132741228718207">
                    <joint name="large_roller_3_5_joint" type="hinge"
                        axis="-0.8090172461742844 -0.5877853418974834 1.997858948277198e-07"
                        pos="-0.015231215181039036 0.03343221014544586 5.017722229196976e-07" />
                    <geom name="large_roller_3_5_geom" type="mesh" mesh="large_roller_link"
                        pos="0 0 0" euler="0 0 0" />
                    <inertial mass="0.026209434773783076"
                        pos="-0.021160269082541185 0.029124611797514622 8.673617379884035e-19"
                        fullinertia="2.9468515731868077e-06 2.7942679958918847e-06 2.6236743710135172e-06 2.348019819418198e-07 3.9387032047324966e-20 -4.552802091491864e-21" />
                </body>
            </body>
            <!-- add imu site -->
            <site name="imu_site" pos="0 0 0.24" size="0.01" />
            <site name="ball_site" pos="0 0 0" size="0.01" />
            <body name="ball_link"
                pos="4.539775579063084e-17 3.9330107106101477e-16 8.699999999969066e-05"
                euler="-1.0148989447430099e-16 -4.996003610813201e-16 1.4198673232204494e-77">
                <joint name="ball_joint" type="ball" pos=" 0.0  0.0  0" damping="0.01" />
                <geom name="ball_geom" type="mesh" mesh="ball_link" pos="0 0 0" euler="0 0 0" />
                <inertial mass="3.021143163744471"
                    pos="2.885352467797298e-17 2.885352467797308e-17 2.886579864025402e-17"
                    fullinertia="0.024537068316026582 0.024537068316026783 0.024537068316026575 1.2502313135099962e-16 2.33620219102254e-17 -1.3441326783345871e-17" />
            </body>
            <camera name="robot_cam" pos="-2.8 0 0.8" euler="0 -1.57 -1.57" />
        </body>
        <!-- <body name="ball_link"
            pos="4.539775579063084e-17 3.9330107106101477e-16 8.699999999969066e-05"
            euler="-1.0148989447430099e-16 -4.996003610813201e-16 1.4198673232204494e-77">
            <joint type="free" damping="0.1"/>
            <geom name="ball_geom" type="mesh" mesh="ball_link" pos="0 0 0" euler="0 0 0" />
            <inertial mass="3.021143163744471"
                pos="2.885352467797298e-17 2.885352467797308e-17 2.886579864025402e-17"
                fullinertia="0.024537068316026582 0.024537068316026783 0.024537068316026575 1.2502313135099962e-16 2.33620219102254e-17 -1.3441326783345871e-17" />
        </body> -->

        <!-- <camera name="robot_cam" pos="-1 0 1" euler="0 -1.57 -1.57"/> -->
    </worldbody>

    <actuator>
        <motor name="wheel_1" joint="wheel_base_1_joint" gear="3" forcerange="-17 17" />
        <motor name="wheel_2" joint="wheel_base_2_joint" gear="3" forcerange="-17 17" />
        <motor name="wheel_3" joint="wheel_base_3_joint" gear="3" forcerange="-17 17" />
<!-- 
        <position class="torso" name="neck" joint="neck_joint" ctrlrange="-3.14 3.14"
            forcerange="-17 17" />
        <position class="torso" name="head" joint="head_joint" ctrlrange="-0.2 0.5"
            forcerange="-17 17" />

        <position class="torso" name="right_shoulder_pitch" joint="right_shoulder_pitch_joint"
            ctrlrange="-3 3" forcerange="-17 17" />
        <position class="torso" name="right_shoulder_roll" joint="right_shoulder_roll_joint"
            ctrlrange="-3 1" forcerange="-17 17" />
        <position class="torso" name="right_shoulder_yaw" joint="right_shoulder_yaw_joint"
            ctrlrange="-3.14 3.14" forcerange="-17 17" />
        <position class="torso" name="right_elbow" joint="right_elbow_joint" ctrlrange="-2.1 2.1"
            forcerange="-17 17" />

        <position class="torso" name="left_shoulder_pitch" joint="left_shoulder_pitch_joint"
            ctrlrange="-3 3" forcerange="-17 17" />
        <position class="torso" name="left_shoulder_roll" joint="left_shoulder_roll_joint"
            ctrlrange="-1 3" forcerange="-17 17" />
        <position class="torso" name="left_shoulder_yaw" joint="left_shoulder_yaw_joint"
            ctrlrange="-3.14 3.14" forcerange="-17 17" />
        <position class="torso" name="left_elbow" joint="left_elbow_joint" ctrlrange="-2.1 2.1"
            forcerange="-17 17" /> -->
    </actuator>

    <sensor>
        <jointpos name="wheel_1_pos" joint="wheel_base_1_joint" />
        <jointpos name="wheel_2_pos" joint="wheel_base_2_joint" />
        <jointpos name="wheel_3_pos" joint="wheel_base_3_joint" />
        <jointvel name="wheel_1_vel" joint="wheel_base_1_joint" />
        <jointvel name="wheel_2_vel" joint="wheel_base_2_joint" />
        <jointvel name="wheel_3_vel" joint="wheel_base_3_joint" />

        <jointactuatorfrc name="whl_1_tor" joint="wheel_base_1_joint" />
        <jointactuatorfrc name="whl_2_tor" joint="wheel_base_2_joint" />
        <jointactuatorfrc name="whl_3_tor" joint="wheel_base_3_joint" />

        <gyro name="imu_gyro" site="imu_site" />
        <velocimeter name="ball_vel" site="ball_site" />
        <framequat name="imu_quat" objtype="site" objname="imu_site" />
        <framepos name="ball_pos" objtype="site" objname="ball_site" />
    </sensor>

</mujoco>